Workbook

Sheet 7月产能数据
B1: APP开发 | D1: 后端开发 | F1: Web开发 | H1: 中台开发 | M1: AI开发 | O1: 测试部-应用软件测试 | Q1: 欧洲办公室 | T1: 云平台总人数 | V1: 项目 | W1: APP | X1: WEB | Y1: 后端 | Z1: 云服务投入总人力 | AA1: 所属产品线 | AB1: 备注 | AC1: 确认人 | AD1: 是否确认
B2: 阳光云 | C2: 平台 | D2: 阳光云 | E2: 平台 | F2: 阳光云 | G2: 平台 | H2: IoT中台 | I2: 技术中台 | J2: 数据中台 | K2: 平台运维 | L2: 业务中台（平台） | M2: 交互智能 | N2: 系统智能 | O2: 云服务 | P2: 中后台 | Q2: APP | R2: WEB | S2: 测试 | V2: AI小助手 | X2: 0 | Y2: 0.5 | Z2: =SUM(W2:Y2) -> 0.5 | AA2: 智慧能源 | AC2: 郭海涛 | AD2: TRUE
A3: 正式人数 | B3: 6 | D3: 6 | E3: 4.5 | F3: 4.7 | H3: 9 | I3: 5 | J3: 11 | K3: 6 | O3: 5.5 | P3: 2.5 | T3: =SUM(B3:S3) -> 60.2 | V3: 新iHM | W3: 2 | X3: 0 | Y3: 0 | Z3: =SUM(W3:Y3) -> 2 | AA3: 智慧能源 | AC3: 王杰 | AD3: FALSE
A4: 外包人数 | B4: 2 | D4: 2.5 | F4: 1 | H4: 0 | I4: 0 | J4: 0 | K4: 0 | O4: 11 | P4: 1 | T4: =SUM(B4:S4) -> 17.5 | V4: 阳光云多场景融合1.0 | W4: 10 | X4: 1 | Y4: 4 | Z4: =SUM(W4:Y4) -> 15 | AA4: 智慧能源 | AC4: 邓荣 | AD4: TRUE
A5: 总人数 | B5: =SUM(B3:B4) -> 8 | C5: =SUM(C3:C4) -> 0 | D5: =SUM(D3:D4) -> 8.5 | E5: =SUM(E3:E4) -> 4.5 | F5: =SUM(F3:F4) -> 5.7 | G5: =SUM(G3:G4) -> 0 | H5: =SUM(H3:H4) -> 9 | I5: =SUM(I3:I4) -> 5 | ... S5: =SUM(S3:S4) -> 0 | T5: =SUM(B5:S5) -> 77.7 | V5: iSolarDesign | W5: 0 | X5: 1 | Y5: 2 | Z5: =SUM(W5:Y5) -> 3 | AA5: 智慧能源 | AC5: 毕道伟 | AD5: TRUE
V6: 亚非拉离网项目 | W6: 0 | X6: 0 | Y6: 0 | Z6: =SUM(W6:Y6) -> 0 | AA6: 智慧能源 | AC6: 邱换春 | AD6: TRUE
V7: 微电网上云 | W7: 0 | X7: 1 | Y7: 0 | Z7: =SUM(W7:Y7) -> 1 | AA7: 智慧能源 | AC7: 王耀东 | AD7: TRUE
V8: iHM 3.0 AI 进阶收益提升项目 | W8: 2 | Y8: 1 | AA8: 智慧能源 | AC8: 毕道伟
V9: 泽塔电池 | W9: 2 | Y9: 0 | AC9: 邱换春
V12: 项目投入 | W12: =SUM(W2:W11) -> 16 | X12: =SUM(X2:X11) -> 3 | Y12: =SUM(Y2:Y11) -> 7.5 | Z12: =SUM(Z2:Z11) -> 21.5
A13: 版本上线时间 | V13: 迭代剩余 | W13: =B5 -> 8 | X13: =F5 -> 5.7 | Y13: =D5 -> 8.5
A14: 封版时间 | B14: 上线时间 | C14: 工作日 | D14: 周六天数 | E14: 开发周期 | F14: 是否采用 | V14: 合计 | W14: =SUM(W12:W13) -> 24 | X14: =SUM(X12:X13) -> 8.7 | Y14: =SUM(Y12:Y13) -> 16
A15: 8.1 | B15: 8.13 | C15: 25 | D15: 3 | E15: =SUM(C15:D15) -> 28 | F15: TRUE
A16: 结论： 1、发布7.23小版本，发布8.13正式版本； 2、研发天数共 28天：工作日 25天，周末3天；

Sheet 规划与产能分析
A1: 产品线版本工作量汇总
A2: 产线 | B2: APP开发-阳光云 | C2: APP开发-平台 | D2: 后端开发-阳光云 | E2: 后端开发-平台 | F2: Web开发-阳光云 | G2: Web开发-平台 | H2: 中台开发-IoT中台 | I2: 中台开发-技术中台 | J2: 中台开发-数据中台 | K2: 中台开发-平台运维 | L2: AI开发-交互智能 | M2: AI开发-系统智能 | N2: 测试部-应用软件测试-云服务 | O2: 测试部-应用软件测试-中后台 | P2: 欧洲办公室-APP | Q2: 欧洲办公室-WEB | R2: 欧洲办公室-测试 | S2: 版本工作量（人天）
A3: 户用及分布式监控 | B3: =IF(B$2="测试部-应用软件测试-云服务",SUMIFS('人力工时数据'!$D:$D,'人力工时数据'!$H:$H,"户用及分布式监控",'人力工时数据'!$B:$B,B$2),SUMIFS('人力工时数据'!$C:$C,'人力工时数据'!$H:$H,"户用及分布式监控",'人力工时数据'!$B:$B,B$2)+IF(LEFT(B$2,4)="中台开发",SUMIFS('人力工时数据'!$E:$E,'人力工时数据'!$H:$H,"户用及分布式监控",'人力工时数据'!$B:$B,B$2),0)) -> 56 | C3: =IF(C$2="测试部-应用软件测试-云服务",SUMIFS('人力工时数据'!$D:$D,'人力工时数据'!$H:$H,"户用及分布式监控",'人力工时数据'!$B:$B,C$2),SUMIFS('人力工时数据'!$C:$C,'人力工时数据'!$H:$H,"户用及分布式监控",'人力工时数据'!$B:$B,C$2)+IF(LEFT(C$2,4)="中台开发",SUMIFS('人力工时数据'!$E:$E,'人力工时数据'!$H:$H,"户用及分布式监控",'人力工时数据'!$B:$B,C$2),0)) -> 0 | D3: =IF(D$2="测试部-应用软件测试-云服务",SUMIFS('人力工时数据'!$D:$D,'人力工时数据'!$H:$H,"户用及分布式监控",'人力工时数据'!$B:$B,D$2),SUMIFS('人力工时数据'!$C:$C,'人力工时数据'!$H:$H,"户用及分布式监控",'人力工时数据'!$B:$B,D$2)+IF(LEFT(D$2,4)="中台开发",SUMIFS('人力工时数据'!$E:$E,'人力工时数据'!$H:$H,"户用及分布式监控",'人力工时数据'!$B:$B,D$2),0)) -> 137.6 | E3: =IF(E$2="测试部-应用软件测试-云服务",SUMIFS('人力工时数据'!$D:$D,'人力工时数据'!$H:$H,"户用及分布式监控",'人力工时数据'!$B:$B,E$2),SUMIFS('人力工时数据'!$C:$C,'人力工时数据'!$H:$H,"户用及分布式监控",'人力工时数据'!$B:$B,E$2)+IF(LEFT(E$2,4)="中台开发",SUMIFS('人力工时数据'!$E:$E,'人力工时数据'!$H:$H,"户用及分布式监控",'人力工时数据'!$B:$B,E$2),0)) -> 19 | F3: =IF(F$2="测试部-应用软件测试-云服务",SUMIFS('人力工时数据'!$D:$D,'人力工时数据'!$H:$H,"户用及分布式监控",'人力工时数据'!$B:$B,F$2),SUMIFS('人力工时数据'!$C:$C,'人力工时数据'!$H:$H,"户用及分布式监控",'人力工时数据'!$B:$B,F$2)+IF(LEFT(F$2,4)="中台开发",SUMIFS('人力工时数据'!$E:$E,'人力工时数据'!$H:$H,"户用及分布式监控",'人力工时数据'!$B:$B,F$2),0)) -> 56.5 | G3: =IF(G$2="测试部-应用软件测试-云服务",SUMIFS('人力工时数据'!$D:$D,'人力工时数据'!$H:$H,"户用及分布式监控",'人力工时数据'!$B:$B,G$2),SUMIFS('人力工时数据'!$C:$C,'人力工时数据'!$H:$H,"户用及分布式监控",'人力工时数据'!$B:$B,G$2)+IF(LEFT(G$2,4)="中台开发",SUMIFS('人力工时数据'!$E:$E,'人力工时数据'!$H:$H,"户用及分布式监控",'人力工时数据'!$B:$B,G$2),0)) -> 0 | H3: =IF(H$2="测试部-应用软件测试-云服务",SUMIFS('人力工时数据'!$D:$D,'人力工时数据'!$H:$H,"户用及分布式监控",'人力工时数据'!$B:$B,H$2),SUMIFS('人力工时数据'!$C:$C,'人力工时数据'!$H:$H,"户用及分布式监控",'人力工时数据'!$B:$B,H$2)+IF(LEFT(H$2,4)="中台开发",SUMIFS('人力工时数据'!$E:$E,'人力工时数据'!$H:$H,"户用及分布式监控",'人力工时数据'!$B:$B,H$2),0)) -> 39 | I3: =IF(I$2="测试部-应用软件测试-云服务",SUMIFS('人力工时数据'!$D:$D,'人力工时数据'!$H:$H,"户用及分布式监控",'人力工时数据'!$B:$B,I$2),SUMIFS('人力工时数据'!$C:$C,'人力工时数据'!$H:$H,"户用及分布式监控",'人力工时数据'!$B:$B,I$2)+IF(LEFT(I$2,4)="中台开发",SUMIFS('人力工时数据'!$E:$E,'人力工时数据'!$H:$H,"户用及分布式监控",'人力工时数据'!$B:$B,I$2),0)) -> 0 | ... R3: =IF(R$2="测试部-应用软件测试-云服务",SUMIFS('人力工时数据'!$D:$D,'人力工时数据'!$H:$H,"户用及分布式监控",'人力工时数据'!$B:$B,R$2),SUMIFS('人力工时数据'!$C:$C,'人力工时数据'!$H:$H,"户用及分布式监控",'人力工时数据'!$B:$B,R$2)+IF(LEFT(R$2,4)="中台开发",SUMIFS('人力工时数据'!$E:$E,'人力工时数据'!$H:$H,"户用及分布式监控",'人力工时数据'!$B:$B,R$2),0)) -> 0 | S3: =SUM(B3:R3) -> 543.1
A4: 储能及地面监控 | B4: =IF(B$2="测试部-应用软件测试-云服务",SUMIFS('人力工时数据'!$D:$D,'人力工时数据'!$H:$H,"储能及地面监控",'人力工时数据'!$B:$B,B$2),SUMIFS('人力工时数据'!$C:$C,'人力工时数据'!$H:$H,"储能及地面监控",'人力工时数据'!$B:$B,B$2)+IF(LEFT(B$2,4)="中台开发",SUMIFS('人力工时数据'!$E:$E,'人力工时数据'!$H:$H,"储能及地面监控",'人力工时数据'!$B:$B,B$2),0)) -> 47 | C4: =IF(C$2="测试部-应用软件测试-云服务",SUMIFS('人力工时数据'!$D:$D,'人力工时数据'!$H:$H,"储能及地面监控",'人力工时数据'!$B:$B,C$2),SUMIFS('人力工时数据'!$C:$C,'人力工时数据'!$H:$H,"储能及地面监控",'人力工时数据'!$B:$B,C$2)+IF(LEFT(C$2,4)="中台开发",SUMIFS('人力工时数据'!$E:$E,'人力工时数据'!$H:$H,"储能及地面监控",'人力工时数据'!$B:$B,C$2),0)) -> 0 | D4: =IF(D$2="测试部-应用软件测试-云服务",SUMIFS('人力工时数据'!$D:$D,'人力工时数据'!$H:$H,"储能及地面监控",'人力工时数据'!$B:$B,D$2),SUMIFS('人力工时数据'!$C:$C,'人力工时数据'!$H:$H,"储能及地面监控",'人力工时数据'!$B:$B,D$2)+IF(LEFT(D$2,4)="中台开发",SUMIFS('人力工时数据'!$E:$E,'人力工时数据'!$H:$H,"储能及地面监控",'人力工时数据'!$B:$B,D$2),0)) -> 46 | E4: =IF(E$2="测试部-应用软件测试-云服务",SUMIFS('人力工时数据'!$D:$D,'人力工时数据'!$H:$H,"储能及地面监控",'人力工时数据'!$B:$B,E$2),SUMIFS('人力工时数据'!$C:$C,'人力工时数据'!$H:$H,"储能及地面监控",'人力工时数据'!$B:$B,E$2)+IF(LEFT(E$2,4)="中台开发",SUMIFS('人力工时数据'!$E:$E,'人力工时数据'!$H:$H,"储能及地面监控",'人力工时数据'!$B:$B,E$2),0)) -> 1 | F4: =IF(F$2="测试部-应用软件测试-云服务",SUMIFS('人力工时数据'!$D:$D,'人力工时数据'!$H:$H,"储能及地面监控",'人力工时数据'!$B:$B,F$2),SUMIFS('人力工时数据'!$C:$C,'人力工时数据'!$H:$H,"储能及地面监控",'人力工时数据'!$B:$B,F$2)+IF(LEFT(F$2,4)="中台开发",SUMIFS('人力工时数据'!$E:$E,'人力工时数据'!$H:$H,"储能及地面监控",'人力工时数据'!$B:$B,F$2),0)) -> 15 | G4: =IF(G$2="测试部-应用软件测试-云服务",SUMIFS('人力工时数据'!$D:$D,'人力工时数据'!$H:$H,"储能及地面监控",'人力工时数据'!$B:$B,G$2),SUMIFS('人力工时数据'!$C:$C,'人力工时数据'!$H:$H,"储能及地面监控",'人力工时数据'!$B:$B,G$2)+IF(LEFT(G$2,4)="中台开发",SUMIFS('人力工时数据'!$E:$E,'人力工时数据'!$H:$H,"储能及地面监控",'人力工时数据'!$B:$B,G$2),0)) -> 0 | H4: =IF(H$2="测试部-应用软件测试-云服务",SUMIFS('人力工时数据'!$D:$D,'人力工时数据'!$H:$H,"储能及地面监控",'人力工时数据'!$B:$B,H$2),SUMIFS('人力工时数据'!$C:$C,'人力工时数据'!$H:$H,"储能及地面监控",'人力工时数据'!$B:$B,H$2)+IF(LEFT(H$2,4)="中台开发",SUMIFS('人力工时数据'!$E:$E,'人力工时数据'!$H:$H,"储能及地面监控",'人力工时数据'!$B:$B,H$2),0)) -> 2 | I4: =IF(I$2="测试部-应用软件测试-云服务",SUMIFS('人力工时数据'!$D:$D,'人力工时数据'!$H:$H,"储能及地面监控",'人力工时数据'!$B:$B,I$2),SUMIFS('人力工时数据'!$C:$C,'人力工时数据'!$H:$H,"储能及地面监控",'人力工时数据'!$B:$B,I$2)+IF(LEFT(I$2,4)="中台开发",SUMIFS('人力工时数据'!$E:$E,'人力工时数据'!$H:$H,"储能及地面监控",'人力工时数据'!$B:$B,I$2),0)) -> 0 | ... R4: =IF(R$2="测试部-应用软件测试-云服务",SUMIFS('人力工时数据'!$D:$D,'人力工时数据'!$H:$H,"储能及地面监控",'人力工时数据'!$B:$B,R$2),SUMIFS('人力工时数据'!$C:$C,'人力工时数据'!$H:$H,"储能及地面监控",'人力工时数据'!$B:$B,R$2)+IF(LEFT(R$2,4)="中台开发",SUMIFS('人力工时数据'!$E:$E,'人力工时数据'!$H:$H,"储能及地面监控",'人力工时数据'!$B:$B,R$2),0)) -> 0 | S4: =SUM(B4:R4) -> 203.5
A5: 工商业场景监控（临时） | B5: =IF(B$2="测试部-应用软件测试-云服务",SUMIFS('人力工时数据'!$D:$D,'人力工时数据'!$H:$H,"工商业场景监控（临时）",'人力工时数据'!$B:$B,B$2),SUMIFS('人力工时数据'!$C:$C,'人力工时数据'!$H:$H,"工商业场景监控（临时）",'人力工时数据'!$B:$B,B$2)+IF(LEFT(B$2,4)="中台开发",SUMIFS('人力工时数据'!$E:$E,'人力工时数据'!$H:$H,"工商业场景监控（临时）",'人力工时数据'!$B:$B,B$2),0)) -> 9 | C5: =IF(C$2="测试部-应用软件测试-云服务",SUMIFS('人力工时数据'!$D:$D,'人力工时数据'!$H:$H,"工商业场景监控（临时）",'人力工时数据'!$B:$B,C$2),SUMIFS('人力工时数据'!$C:$C,'人力工时数据'!$H:$H,"工商业场景监控（临时）",'人力工时数据'!$B:$B,C$2)+IF(LEFT(C$2,4)="中台开发",SUMIFS('人力工时数据'!$E:$E,'人力工时数据'!$H:$H,"工商业场景监控（临时）",'人力工时数据'!$B:$B,C$2),0)) -> 0 | D5: =IF(D$2="测试部-应用软件测试-云服务",SUMIFS('人力工时数据'!$D:$D,'人力工时数据'!$H:$H,"工商业场景监控（临时）",'人力工时数据'!$B:$B,D$2),SUMIFS('人力工时数据'!$C:$C,'人力工时数据'!$H:$H,"工商业场景监控（临时）",'人力工时数据'!$B:$B,D$2)+IF(LEFT(D$2,4)="中台开发",SUMIFS('人力工时数据'!$E:$E,'人力工时数据'!$H:$H,"工商业场景监控（临时）",'人力工时数据'!$B:$B,D$2),0)) -> 4.5 | E5: =IF(E$2="测试部-应用软件测试-云服务",SUMIFS('人力工时数据'!$D:$D,'人力工时数据'!$H:$H,"工商业场景监控（临时）",'人力工时数据'!$B:$B,E$2),SUMIFS('人力工时数据'!$C:$C,'人力工时数据'!$H:$H,"工商业场景监控（临时）",'人力工时数据'!$B:$B,E$2)+IF(LEFT(E$2,4)="中台开发",SUMIFS('人力工时数据'!$E:$E,'人力工时数据'!$H:$H,"工商业场景监控（临时）",'人力工时数据'!$B:$B,E$2),0)) -> 3 | F5: =IF(F$2="测试部-应用软件测试-云服务",SUMIFS('人力工时数据'!$D:$D,'人力工时数据'!$H:$H,"工商业场景监控（临时）",'人力工时数据'!$B:$B,F$2),SUMIFS('人力工时数据'!$C:$C,'人力工时数据'!$H:$H,"工商业场景监控（临时）",'人力工时数据'!$B:$B,F$2)+IF(LEFT(F$2,4)="中台开发",SUMIFS('人力工时数据'!$E:$E,'人力工时数据'!$H:$H,"工商业场景监控（临时）",'人力工时数据'!$B:$B,F$2),0)) -> 3 | G5: =IF(G$2="测试部-应用软件测试-云服务",SUMIFS('人力工时数据'!$D:$D,'人力工时数据'!$H:$H,"工商业场景监控（临时）",'人力工时数据'!$B:$B,G$2),SUMIFS('人力工时数据'!$C:$C,'人力工时数据'!$H:$H,"工商业场景监控（临时）",'人力工时数据'!$B:$B,G$2)+IF(LEFT(G$2,4)="中台开发",SUMIFS('人力工时数据'!$E:$E,'人力工时数据'!$H:$H,"工商业场景监控（临时）",'人力工时数据'!$B:$B,G$2),0)) -> 0 | H5: =IF(H$2="测试部-应用软件测试-云服务",SUMIFS('人力工时数据'!$D:$D,'人力工时数据'!$H:$H,"工商业场景监控（临时）",'人力工时数据'!$B:$B,H$2),SUMIFS('人力工时数据'!$C:$C,'人力工时数据'!$H:$H,"工商业场景监控（临时）",'人力工时数据'!$B:$B,H$2)+IF(LEFT(H$2,4)="中台开发",SUMIFS('人力工时数据'!$E:$E,'人力工时数据'!$H:$H,"工商业场景监控（临时）",'人力工时数据'!$B:$B,H$2),0)) -> 9 | I5: =IF(I$2="测试部-应用软件测试-云服务",SUMIFS('人力工时数据'!$D:$D,'人力工时数据'!$H:$H,"工商业场景监控（临时）",'人力工时数据'!$B:$B,I$2),SUMIFS('人力工时数据'!$C:$C,'人力工时数据'!$H:$H,"工商业场景监控（临时）",'人力工时数据'!$B:$B,I$2)+IF(LEFT(I$2,4)="中台开发",SUMIFS('人力工时数据'!$E:$E,'人力工时数据'!$H:$H,"工商业场景监控（临时）",'人力工时数据'!$B:$B,I$2),0)) -> 0 | ... R5: =IF(R$2="测试部-应用软件测试-云服务",SUMIFS('人力工时数据'!$D:$D,'人力工时数据'!$H:$H,"工商业场景监控（临时）",'人力工时数据'!$B:$B,R$2),SUMIFS('人力工时数据'!$C:$C,'人力工时数据'!$H:$H,"工商业场景监控（临时）",'人力工时数据'!$B:$B,R$2)+IF(LEFT(R$2,4)="中台开发",SUMIFS('人力工时数据'!$E:$E,'人力工时数据'!$H:$H,"工商业场景监控（临时）",'人力工时数据'!$B:$B,R$2),0)) -> 0 | S5: =SUM(B5:R5) -> 54.5
A6: 产品线汇总 | B6: =SUM(B3:B5) -> 112 | C6: =SUM(C3:C5) -> 0 | D6: =SUM(D3:D5) -> 188.1 | E6: =SUM(E3:E5) -> 23 | F6: =SUM(F3:F5) -> 74.5 | G6: =SUM(G3:G5) -> 0 | H6: =SUM(H3:H5) -> 50 | I6: =SUM(I3:I5) -> 0 | ... S6: =SUM(S3:S5) -> 801.1
A9: 版本规划工作量汇总
A10: 分类 | B10: APP开发-阳光云 | C10: APP开发-平台 | D10: 后端开发-阳光云 | E10: 后端开发-平台 | F10: Web开发-阳光云 | G10: Web开发-平台 | H10: 中台开发-IoT中台 | I10: 中台开发-技术中台 | J10: 中台开发-数据中台 | K10: 中台开发-平台运维 | L10: AI开发-交互智能 | M10: AI开发-系统智能 | N10: 测试部-应用软件测试-云服务 | O10: 测试部-应用软件测试-中后台 | P10: 欧洲办公室-APP | Q10: 欧洲办公室-WEB | R10: 欧洲办公室-测试 | S10: 需求总人力（人天）
A11: 产品线汇总 | B11: =B6 -> 112 | C11: =C6 -> 0 | D11: =D6 -> 188.1 | E11: =E6 -> 23 | F11: =F6 -> 74.5 | G11: =G6 -> 0 | H11: =H6 -> 50 | I11: =I6 -> 0 | ... S11: =S6 -> 801.1
A12: 未立项/未填写项目 | B12: =IF(B$10="测试部-应用软件测试-云服务",SUM(SUMIFS('人力工时数据'!$D:$D,'人力工时数据'!$H:$H,{"未立项","未填写"},'人力工时数据'!$B:$B,B$10)),SUM(SUMIFS('人力工时数据'!$C:$C,'人力工时数据'!$H:$H,{"未立项","未填写"},'人力工时数据'!$B:$B,B$10))+IF(LEFT(B$10,4)="中台开发",SUM(SUMIFS('人力工时数据'!$E:$E,'人力工时数据'!$H:$H,{"未立项","未填写"},'人力工时数据'!$B:$B,B$10)),0)) -> 0 | C12: =IF(C$10="测试部-应用软件测试-云服务",SUM(SUMIFS('人力工时数据'!$D:$D,'人力工时数据'!$H:$H,{"未立项","未填写"},'人力工时数据'!$B:$B,C$10)),SUM(SUMIFS('人力工时数据'!$C:$C,'人力工时数据'!$H:$H,{"未立项","未填写"},'人力工时数据'!$B:$B,C$10))+IF(LEFT(C$10,4)="中台开发",SUM(SUMIFS('人力工时数据'!$E:$E,'人力工时数据'!$H:$H,{"未立项","未填写"},'人力工时数据'!$B:$B,C$10)),0)) -> 0 | D12: =IF(D$10="测试部-应用软件测试-云服务",SUM(SUMIFS('人力工时数据'!$D:$D,'人力工时数据'!$H:$H,{"未立项","未填写"},'人力工时数据'!$B:$B,D$10)),SUM(SUMIFS('人力工时数据'!$C:$C,'人力工时数据'!$H:$H,{"未立项","未填写"},'人力工时数据'!$B:$B,D$10))+IF(LEFT(D$10,4)="中台开发",SUM(SUMIFS('人力工时数据'!$E:$E,'人力工时数据'!$H:$H,{"未立项","未填写"},'人力工时数据'!$B:$B,D$10)),0)) -> 14 | E12: =IF(E$10="测试部-应用软件测试-云服务",SUM(SUMIFS('人力工时数据'!$D:$D,'人力工时数据'!$H:$H,{"未立项","未填写"},'人力工时数据'!$B:$B,E$10)),SUM(SUMIFS('人力工时数据'!$C:$C,'人力工时数据'!$H:$H,{"未立项","未填写"},'人力工时数据'!$B:$B,E$10))+IF(LEFT(E$10,4)="中台开发",SUM(SUMIFS('人力工时数据'!$E:$E,'人力工时数据'!$H:$H,{"未立项","未填写"},'人力工时数据'!$B:$B,E$10)),0)) -> 3 | F12: =IF(F$10="测试部-应用软件测试-云服务",SUM(SUMIFS('人力工时数据'!$D:$D,'人力工时数据'!$H:$H,{"未立项","未填写"},'人力工时数据'!$B:$B,F$10)),SUM(SUMIFS('人力工时数据'!$C:$C,'人力工时数据'!$H:$H,{"未立项","未填写"},'人力工时数据'!$B:$B,F$10))+IF(LEFT(F$10,4)="中台开发",SUM(SUMIFS('人力工时数据'!$E:$E,'人力工时数据'!$H:$H,{"未立项","未填写"},'人力工时数据'!$B:$B,F$10)),0)) -> 2.5 | G12: =IF(G$10="测试部-应用软件测试-云服务",SUM(SUMIFS('人力工时数据'!$D:$D,'人力工时数据'!$H:$H,{"未立项","未填写"},'人力工时数据'!$B:$B,G$10)),SUM(SUMIFS('人力工时数据'!$C:$C,'人力工时数据'!$H:$H,{"未立项","未填写"},'人力工时数据'!$B:$B,G$10))+IF(LEFT(G$10,4)="中台开发",SUM(SUMIFS('人力工时数据'!$E:$E,'人力工时数据'!$H:$H,{"未立项","未填写"},'人力工时数据'!$B:$B,G$10)),0)) -> 0 | H12: =IF(H$10="测试部-应用软件测试-云服务",SUM(SUMIFS('人力工时数据'!$D:$D,'人力工时数据'!$H:$H,{"未立项","未填写"},'人力工时数据'!$B:$B,H$10)),SUM(SUMIFS('人力工时数据'!$C:$C,'人力工时数据'!$H:$H,{"未立项","未填写"},'人力工时数据'!$B:$B,H$10))+IF(LEFT(H$10,4)="中台开发",SUM(SUMIFS('人力工时数据'!$E:$E,'人力工时数据'!$H:$H,{"未立项","未填写"},'人力工时数据'!$B:$B,H$10)),0)) -> 1 | I12: =IF(I$10="测试部-应用软件测试-云服务",SUM(SUMIFS('人力工时数据'!$D:$D,'人力工时数据'!$H:$H,{"未立项","未填写"},'人力工时数据'!$B:$B,I$10)),SUM(SUMIFS('人力工时数据'!$C:$C,'人力工时数据'!$H:$H,{"未立项","未填写"},'人力工时数据'!$B:$B,I$10))+IF(LEFT(I$10,4)="中台开发",SUM(SUMIFS('人力工时数据'!$E:$E,'人力工时数据'!$H:$H,{"未立项","未填写"},'人力工时数据'!$B:$B,I$10)),0)) -> 72 | ... R12: =IF(R$10="测试部-应用软件测试-云服务",SUM(SUMIFS('人力工时数据'!$D:$D,'人力工时数据'!$H:$H,{"未立项","未填写"},'人力工时数据'!$B:$B,R$10)),SUM(SUMIFS('人力工时数据'!$C:$C,'人力工时数据'!$H:$H,{"未立项","未填写"},'人力工时数据'!$B:$B,R$10))+IF(LEFT(R$10,4)="中台开发",SUM(SUMIFS('人力工时数据'!$E:$E,'人力工时数据'!$H:$H,{"未立项","未填写"},'人力工时数据'!$B:$B,R$10)),0)) -> 0 | S12: =SUM(B12:R12) -> 107
A13: ECO | B13: =IF(B$10="测试部-应用软件测试-云服务",SUMIFS('人力工时数据'!$D:$D,'人力工时数据'!$H:$H,"ECO",'人力工时数据'!$B:$B,B$10),SUMIFS('人力工时数据'!$C:$C,'人力工时数据'!$H:$H,"ECO",'人力工时数据'!$B:$B,B$10)+IF(LEFT(B$10,4)="中台开发",SUMIFS('人力工时数据'!$E:$E,'人力工时数据'!$H:$H,"ECO",'人力工时数据'!$B:$B,B$10),0)) -> 0 | C13: =IF(C$10="测试部-应用软件测试-云服务",SUMIFS('人力工时数据'!$D:$D,'人力工时数据'!$H:$H,"ECO",'人力工时数据'!$B:$B,C$10),SUMIFS('人力工时数据'!$C:$C,'人力工时数据'!$H:$H,"ECO",'人力工时数据'!$B:$B,C$10)+IF(LEFT(C$10,4)="中台开发",SUMIFS('人力工时数据'!$E:$E,'人力工时数据'!$H:$H,"ECO",'人力工时数据'!$B:$B,C$10),0)) -> 0 | D13: =IF(D$10="测试部-应用软件测试-云服务",SUMIFS('人力工时数据'!$D:$D,'人力工时数据'!$H:$H,"ECO",'人力工时数据'!$B:$B,D$10),SUMIFS('人力工时数据'!$C:$C,'人力工时数据'!$H:$H,"ECO",'人力工时数据'!$B:$B,D$10)+IF(LEFT(D$10,4)="中台开发",SUMIFS('人力工时数据'!$E:$E,'人力工时数据'!$H:$H,"ECO",'人力工时数据'!$B:$B,D$10),0)) -> 0 | E13: =IF(E$10="测试部-应用软件测试-云服务",SUMIFS('人力工时数据'!$D:$D,'人力工时数据'!$H:$H,"ECO",'人力工时数据'!$B:$B,E$10),SUMIFS('人力工时数据'!$C:$C,'人力工时数据'!$H:$H,"ECO",'人力工时数据'!$B:$B,E$10)+IF(LEFT(E$10,4)="中台开发",SUMIFS('人力工时数据'!$E:$E,'人力工时数据'!$H:$H,"ECO",'人力工时数据'!$B:$B,E$10),0)) -> 0 | F13: =IF(F$10="测试部-应用软件测试-云服务",SUMIFS('人力工时数据'!$D:$D,'人力工时数据'!$H:$H,"ECO",'人力工时数据'!$B:$B,F$10),SUMIFS('人力工时数据'!$C:$C,'人力工时数据'!$H:$H,"ECO",'人力工时数据'!$B:$B,F$10)+IF(LEFT(F$10,4)="中台开发",SUMIFS('人力工时数据'!$E:$E,'人力工时数据'!$H:$H,"ECO",'人力工时数据'!$B:$B,F$10),0)) -> 0 | G13: =IF(G$10="测试部-应用软件测试-云服务",SUMIFS('人力工时数据'!$D:$D,'人力工时数据'!$H:$H,"ECO",'人力工时数据'!$B:$B,G$10),SUMIFS('人力工时数据'!$C:$C,'人力工时数据'!$H:$H,"ECO",'人力工时数据'!$B:$B,G$10)+IF(LEFT(G$10,4)="中台开发",SUMIFS('人力工时数据'!$E:$E,'人力工时数据'!$H:$H,"ECO",'人力工时数据'!$B:$B,G$10),0)) -> 0 | H13: =IF(H$10="测试部-应用软件测试-云服务",SUMIFS('人力工时数据'!$D:$D,'人力工时数据'!$H:$H,"ECO",'人力工时数据'!$B:$B,H$10),SUMIFS('人力工时数据'!$C:$C,'人力工时数据'!$H:$H,"ECO",'人力工时数据'!$B:$B,H$10)+IF(LEFT(H$10,4)="中台开发",SUMIFS('人力工时数据'!$E:$E,'人力工时数据'!$H:$H,"ECO",'人力工时数据'!$B:$B,H$10),0)) -> 28 | I13: =IF(I$10="测试部-应用软件测试-云服务",SUMIFS('人力工时数据'!$D:$D,'人力工时数据'!$H:$H,"ECO",'人力工时数据'!$B:$B,I$10),SUMIFS('人力工时数据'!$C:$C,'人力工时数据'!$H:$H,"ECO",'人力工时数据'!$B:$B,I$10)+IF(LEFT(I$10,4)="中台开发",SUMIFS('人力工时数据'!$E:$E,'人力工时数据'!$H:$H,"ECO",'人力工时数据'!$B:$B,I$10),0)) -> 0 | ... R13: =IF(R$10="测试部-应用软件测试-云服务",SUMIFS('人力工时数据'!$D:$D,'人力工时数据'!$H:$H,"ECO",'人力工时数据'!$B:$B,R$10),SUMIFS('人力工时数据'!$C:$C,'人力工时数据'!$H:$H,"ECO",'人力工时数据'!$B:$B,R$10)+IF(LEFT(R$10,4)="中台开发",SUMIFS('人力工时数据'!$E:$E,'人力工时数据'!$H:$H,"ECO",'人力工时数据'!$B:$B,R$10),0)) -> 0 | S13: =SUM(B13:R13) -> 59
A14: 工具项目 | B14: =IF(B$10="测试部-应用软件测试-云服务",SUMIFS('人力工时数据'!$D:$D,'人力工时数据'!$H:$H,"工具项目",'人力工时数据'!$B:$B,B$10),SUMIFS('人力工时数据'!$C:$C,'人力工时数据'!$H:$H,"工具项目",'人力工时数据'!$B:$B,B$10)+IF(LEFT(B$10,4)="中台开发",SUMIFS('人力工时数据'!$E:$E,'人力工时数据'!$H:$H,"工具项目",'人力工时数据'!$B:$B,B$10),0)) -> 0 | C14: =IF(C$10="测试部-应用软件测试-云服务",SUMIFS('人力工时数据'!$D:$D,'人力工时数据'!$H:$H,"工具项目",'人力工时数据'!$B:$B,C$10),SUMIFS('人力工时数据'!$C:$C,'人力工时数据'!$H:$H,"工具项目",'人力工时数据'!$B:$B,C$10)+IF(LEFT(C$10,4)="中台开发",SUMIFS('人力工时数据'!$E:$E,'人力工时数据'!$H:$H,"工具项目",'人力工时数据'!$B:$B,C$10),0)) -> 0 | D14: =IF(D$10="测试部-应用软件测试-云服务",SUMIFS('人力工时数据'!$D:$D,'人力工时数据'!$H:$H,"工具项目",'人力工时数据'!$B:$B,D$10),SUMIFS('人力工时数据'!$C:$C,'人力工时数据'!$H:$H,"工具项目",'人力工时数据'!$B:$B,D$10)+IF(LEFT(D$10,4)="中台开发",SUMIFS('人力工时数据'!$E:$E,'人力工时数据'!$H:$H,"工具项目",'人力工时数据'!$B:$B,D$10),0)) -> 0 | E14: =IF(E$10="测试部-应用软件测试-云服务",SUMIFS('人力工时数据'!$D:$D,'人力工时数据'!$H:$H,"工具项目",'人力工时数据'!$B:$B,E$10),SUMIFS('人力工时数据'!$C:$C,'人力工时数据'!$H:$H,"工具项目",'人力工时数据'!$B:$B,E$10)+IF(LEFT(E$10,4)="中台开发",SUMIFS('人力工时数据'!$E:$E,'人力工时数据'!$H:$H,"工具项目",'人力工时数据'!$B:$B,E$10),0)) -> 0 | F14: =IF(F$10="测试部-应用软件测试-云服务",SUMIFS('人力工时数据'!$D:$D,'人力工时数据'!$H:$H,"工具项目",'人力工时数据'!$B:$B,F$10),SUMIFS('人力工时数据'!$C:$C,'人力工时数据'!$H:$H,"工具项目",'人力工时数据'!$B:$B,F$10)+IF(LEFT(F$10,4)="中台开发",SUMIFS('人力工时数据'!$E:$E,'人力工时数据'!$H:$H,"工具项目",'人力工时数据'!$B:$B,F$10),0)) -> 0 | G14: =IF(G$10="测试部-应用软件测试-云服务",SUMIFS('人力工时数据'!$D:$D,'人力工时数据'!$H:$H,"工具项目",'人力工时数据'!$B:$B,G$10),SUMIFS('人力工时数据'!$C:$C,'人力工时数据'!$H:$H,"工具项目",'人力工时数据'!$B:$B,G$10)+IF(LEFT(G$10,4)="中台开发",SUMIFS('人力工时数据'!$E:$E,'人力工时数据'!$H:$H,"工具项目",'人力工时数据'!$B:$B,G$10),0)) -> 0 | H14: =IF(H$10="测试部-应用软件测试-云服务",SUMIFS('人力工时数据'!$D:$D,'人力工时数据'!$H:$H,"工具项目",'人力工时数据'!$B:$B,H$10),SUMIFS('人力工时数据'!$C:$C,'人力工时数据'!$H:$H,"工具项目",'人力工时数据'!$B:$B,H$10)+IF(LEFT(H$10,4)="中台开发",SUMIFS('人力工时数据'!$E:$E,'人力工时数据'!$H:$H,"工具项目",'人力工时数据'!$B:$B,H$10),0)) -> 1 | I14: =IF(I$10="测试部-应用软件测试-云服务",SUMIFS('人力工时数据'!$D:$D,'人力工时数据'!$H:$H,"工具项目",'人力工时数据'!$B:$B,I$10),SUMIFS('人力工时数据'!$C:$C,'人力工时数据'!$H:$H,"工具项目",'人力工时数据'!$B:$B,I$10)+IF(LEFT(I$10,4)="中台开发",SUMIFS('人力工时数据'!$E:$E,'人力工时数据'!$H:$H,"工具项目",'人力工时数据'!$B:$B,I$10),0)) -> 0 | ... R14: =IF(R$10="测试部-应用软件测试-云服务",SUMIFS('人力工时数据'!$D:$D,'人力工时数据'!$H:$H,"工具项目",'人力工时数据'!$B:$B,R$10),SUMIFS('人力工时数据'!$C:$C,'人力工时数据'!$H:$H,"工具项目",'人力工时数据'!$B:$B,R$10)+IF(LEFT(R$10,4)="中台开发",SUMIFS('人力工时数据'!$E:$E,'人力工时数据'!$H:$H,"工具项目",'人力工时数据'!$B:$B,R$10),0)) -> 0 | S14: =SUM(B14:R14) -> 7
A15: 智慧能源产品中心 | B15: =IF(B$10="测试部-应用软件测试-云服务",SUMIFS('人力工时数据'!$D:$D,'人力工时数据'!$H:$H,"智慧能源产品中心",'人力工时数据'!$B:$B,B$10),SUMIFS('人力工时数据'!$C:$C,'人力工时数据'!$H:$H,"智慧能源产品中心",'人力工时数据'!$B:$B,B$10)+IF(LEFT(B$10,4)="中台开发",SUMIFS('人力工时数据'!$E:$E,'人力工时数据'!$H:$H,"智慧能源产品中心",'人力工时数据'!$B:$B,B$10),0)) -> 112.5 | C15: =IF(C$10="测试部-应用软件测试-云服务",SUMIFS('人力工时数据'!$D:$D,'人力工时数据'!$H:$H,"智慧能源产品中心",'人力工时数据'!$B:$B,C$10),SUMIFS('人力工时数据'!$C:$C,'人力工时数据'!$H:$H,"智慧能源产品中心",'人力工时数据'!$B:$B,C$10)+IF(LEFT(C$10,4)="中台开发",SUMIFS('人力工时数据'!$E:$E,'人力工时数据'!$H:$H,"智慧能源产品中心",'人力工时数据'!$B:$B,C$10),0)) -> 49 | D15: =IF(D$10="测试部-应用软件测试-云服务",SUMIFS('人力工时数据'!$D:$D,'人力工时数据'!$H:$H,"智慧能源产品中心",'人力工时数据'!$B:$B,D$10),SUMIFS('人力工时数据'!$C:$C,'人力工时数据'!$H:$H,"智慧能源产品中心",'人力工时数据'!$B:$B,D$10)+IF(LEFT(D$10,4)="中台开发",SUMIFS('人力工时数据'!$E:$E,'人力工时数据'!$H:$H,"智慧能源产品中心",'人力工时数据'!$B:$B,D$10),0)) -> 227.5 | E15: =IF(E$10="测试部-应用软件测试-云服务",SUMIFS('人力工时数据'!$D:$D,'人力工时数据'!$H:$H,"智慧能源产品中心",'人力工时数据'!$B:$B,E$10),SUMIFS('人力工时数据'!$C:$C,'人力工时数据'!$H:$H,"智慧能源产品中心",'人力工时数据'!$B:$B,E$10)+IF(LEFT(E$10,4)="中台开发",SUMIFS('人力工时数据'!$E:$E,'人力工时数据'!$H:$H,"智慧能源产品中心",'人力工时数据'!$B:$B,E$10),0)) -> 70 | F15: =IF(F$10="测试部-应用软件测试-云服务",SUMIFS('人力工时数据'!$D:$D,'人力工时数据'!$H:$H,"智慧能源产品中心",'人力工时数据'!$B:$B,F$10),SUMIFS('人力工时数据'!$C:$C,'人力工时数据'!$H:$H,"智慧能源产品中心",'人力工时数据'!$B:$B,F$10)+IF(LEFT(F$10,4)="中台开发",SUMIFS('人力工时数据'!$E:$E,'人力工时数据'!$H:$H,"智慧能源产品中心",'人力工时数据'!$B:$B,F$10),0)) -> 148.5 | G15: =IF(G$10="测试部-应用软件测试-云服务",SUMIFS('人力工时数据'!$D:$D,'人力工时数据'!$H:$H,"智慧能源产品中心",'人力工时数据'!$B:$B,G$10),SUMIFS('人力工时数据'!$C:$C,'人力工时数据'!$H:$H,"智慧能源产品中心",'人力工时数据'!$B:$B,G$10)+IF(LEFT(G$10,4)="中台开发",SUMIFS('人力工时数据'!$E:$E,'人力工时数据'!$H:$H,"智慧能源产品中心",'人力工时数据'!$B:$B,G$10),0)) -> 0 | H15: =IF(H$10="测试部-应用软件测试-云服务",SUMIFS('人力工时数据'!$D:$D,'人力工时数据'!$H:$H,"智慧能源产品中心",'人力工时数据'!$B:$B,H$10),SUMIFS('人力工时数据'!$C:$C,'人力工时数据'!$H:$H,"智慧能源产品中心",'人力工时数据'!$B:$B,H$10)+IF(LEFT(H$10,4)="中台开发",SUMIFS('人力工时数据'!$E:$E,'人力工时数据'!$H:$H,"智慧能源产品中心",'人力工时数据'!$B:$B,H$10),0)) -> 173 | I15: =IF(I$10="测试部-应用软件测试-云服务",SUMIFS('人力工时数据'!$D:$D,'人力工时数据'!$H:$H,"智慧能源产品中心",'人力工时数据'!$B:$B,I$10),SUMIFS('人力工时数据'!$C:$C,'人力工时数据'!$H:$H,"智慧能源产品中心",'人力工时数据'!$B:$B,I$10)+IF(LEFT(I$10,4)="中台开发",SUMIFS('人力工时数据'!$E:$E,'人力工时数据'!$H:$H,"智慧能源产品中心",'人力工时数据'!$B:$B,I$10),0)) -> 74 | ... R15: =IF(R$10="测试部-应用软件测试-云服务",SUMIFS('人力工时数据'!$D:$D,'人力工时数据'!$H:$H,"智慧能源产品中心",'人力工时数据'!$B:$B,R$10),SUMIFS('人力工时数据'!$C:$C,'人力工时数据'!$H:$H,"智慧能源产品中心",'人力工时数据'!$B:$B,R$10)+IF(LEFT(R$10,4)="中台开发",SUMIFS('人力工时数据'!$E:$E,'人力工时数据'!$H:$H,"智慧能源产品中心",'人力工时数据'!$B:$B,R$10),0)) -> 18 | S15: =SUM(B15:R15) -> 1547.5
A16: 合计 | B16: 224.5 | C16: 49 | D16: 429.6 | E16: 96 | F16: 225.5 | G16: 0 | H16: 253 | I16: 146 | J16: 320 | K16: 125 | L16: 0 | M16: 0 | N16: 481 | O16: 129 | P16: 15 | Q16: 10 | R16: 18 | S16: =SUM(S11:S15) -> 2521.6
A19: 云团队产能明细
A20: 人数 | T20: 产能
A21: 员工类型 | B21: APP开发-阳光云 | C21: APP开发-平台 | D21: 后端开发-阳光云 | E21: 后端开发-平台 | F21: Web开发-阳光云 | G21: Web开发-平台 | H21: 中台开发-IoT中台 | I21: 中台开发-技术中台 | J21: 中台开发-数据中台 | K21: 中台开发-平台运维 | L21: AI开发-交互智能 | M21: AI开发-系统智能 | N21: 测试部-应用软件测试-云服务 | O21: 测试部-应用软件测试-中后台 | P21: 欧洲办公室-APP | Q21: 欧洲办公室-WEB | R21: 欧洲办公室-测试 | S21: 总人数 | T21: 研发天数 | U21: 产能-APP开发-阳光云 | V21: 产能-APP开发-平台 | W21: 产能-后端开发-阳光云 | X21: 产能-后端开发-平台 | Y21: 产能-Web开发-阳光云 | Z21: 产能-Web开发-平台 | AA21: 产能-中台开发-IoT中台 | AB21: 产能-中台开发-技术中台 | AC21: 产能-中台开发-数据中台 | AD21: 产能-中台开发-平台运维 | AE21: 产能-中台开发-业务中台（平台） | AF21: 产能-AI开发-交互智能 | AG21: 产能-AI开发-系统智能 | AH21: 产能-测试部-应用软件测试-云服务 | AI21: 产能-测试部-应用软件测试-中后台 | AJ21: 产能-欧洲办公室-APP | AK21: 产能-欧洲办公室-WEB | AL21: 产能-欧洲办公室-测试 | AM21: 总产能
A22: 正式 | B22: ='7月产能数据'!B3 -> 6 | C22: ='7月产能数据'!C3 -> 0 | D22: ='7月产能数据'!D3 -> 6 | E22: ='7月产能数据'!E3 -> 4.5 | F22: ='7月产能数据'!F3 -> 4.7 | G22: ='7月产能数据'!G3 -> 0 | H22: ='7月产能数据'!H3 -> 9 | I22: 5 | J22: ='7月产能数据'!J3 -> 11 | K22: ='7月产能数据'!K3 -> 6 | L22: ='7月产能数据'!M3 -> 0 | M22: ='7月产能数据'!N3 -> 0 | N22: ='7月产能数据'!O3 -> 5.5 | O22: ='7月产能数据'!P3 -> 2.5 | P22: 8 | Q22: 3 | R22: 3 | S22: =SUM(B22:R22) -> 74.2 | T22: =Q28 -> 16 | U22: =B22*$T$22 -> 96 | V22: =C22*$T$22 -> 0 | W22: =D22*$T$22 -> 96 | X22: =E22*$T$22 -> 72 | Y22: =F22*$T$22 -> 75.2 | Z22: =G22*$T$22 -> 0 | AA22: =H22*$T$22 -> 144 | AB22: =I22*$T$22 -> 80 | ... AD22: =K22*$T$22 -> 96 | AE22: =#REF!*$T$22 -> #REF! | AF22: =L22*$T$22 -> 0 | AG22: =M22*$T$22 -> 0 | AH22: =N22*$T$22 -> 88 | AI22: =O22*$T$22 -> 40 | AJ22: =P22*$T$22 -> 128 | AK22: =Q22*$T$22 -> 48 | AL22: =R22*$T$22 -> 48 | AM22: =SUM(U22:AL22) -> #REF!
A23: 外包 | B23: ='7月产能数据'!B4 -> 2 | C23: ='7月产能数据'!C4 -> 0 | D23: ='7月产能数据'!D4 -> 2.5 | E23: ='7月产能数据'!E4 -> 0 | F23: ='7月产能数据'!F4 -> 1 | G23: ='7月产能数据'!G4 -> 0 | H23: ='7月产能数据'!H4 -> 0 | I23: ='7月产能数据'!I4 -> 0 | ... K23: ='7月产能数据'!K4 -> 0 | L23: ='7月产能数据'!M4 -> 0 | M23: ='7月产能数据'!N4 -> 0 | N23: ='7月产能数据'!O4 -> 11 | O23: ='7月产能数据'!P4 -> 1 | P23: ='7月产能数据'!Q4 -> 0 | Q23: ='7月产能数据'!R4 -> 0 | R23: ='7月产能数据'!S4 -> 0 | S23: =SUM(B23:R23) -> 17.5 | T23: =$T$22 -> 16 | U23: =B23*$T$22 -> 32 | V23: =C23*$T$22 -> 0 | W23: =D23*$T$22 -> 40 | X23: =E23*$T$22 -> 0 | Y23: =F23*$T$22 -> 16 | Z23: =G23*$T$22 -> 0 | AA23: =H23*$T$22 -> 0 | AB23: =I23*$T$22 -> 0 | ... AD23: =K23*$T$22 -> 0 | AE23: =#REF!*$T$22 -> #REF! | AF23: =L23*$T$22 -> 0 | AG23: =M23*$T$22 -> 0 | AH23: =N23*$T$22 -> 176 | AI23: =O23*$T$22 -> 16 | AJ23: =P23*$T$22 -> 0 | AK23: =Q23*$T$22 -> 0 | AL23: =R23*$T$22 -> 0 | AM23: =SUM(U23:AL23) -> #REF!
A24: 汇总 | B24: =SUM(B22:B23) -> 8 | C24: =SUM(C22:C23) -> 0 | D24: =SUM(D22:D23) -> 8.5 | E24: =SUM(E22:E23) -> 4.5 | F24: =SUM(F22:F23) -> 5.7 | G24: =SUM(G22:G23) -> 0 | H24: =SUM(H22:H23) -> 9 | I24: 5 | J24: =SUM(J22:J23) -> 11 | K24: =SUM(K22:K23) -> 6 | L24: =SUM(L22:L23) -> 0 | M24: =SUM(M22:M23) -> 0 | N24: =SUM(N22:N23) -> 16.5 | O24: =SUM(O22:O23) -> 3.5 | P24: =SUM(P22:P23) -> 8 | Q24: =SUM(Q22:Q23) -> 3 | R24: =SUM(R22:R23) -> 3 | S24: =SUM(B24:R24) -> 91.7 | T24: =$T$22 -> 16 | U24: =B24*$T$22 -> 128 | V24: =C24*$T$22 -> 0 | W24: =D24*$T$22 -> 136 | X24: =E24*$T$22 -> 72 | Y24: =F24*$T$22 -> 91.2 | Z24: =G24*$T$22 -> 0 | AA24: =H24*$T$22 -> 144 | AB24: =I24*$T$22 -> 80 | ... AD24: =K24*$T$22 -> 96 | AE24: =#REF!*$T$22 -> #REF! | AF24: =L24*$T$22 -> 0 | AG24: =M24*$T$22 -> 0 | AH24: =N24*$T$22 -> 264 | AI24: =O24*$T$22 -> 56 | AJ24: =P24*$T$22 -> 128 | AK24: =Q24*$T$22 -> 48 | AL24: =R24*$T$22 -> 48 | AM24: =SUM(U24:AL24) -> #REF!
A26: 团队版本工作量与团队产能偏差分析 | M26: 版本上线时间
A27: 团队 | B27: 版本工作量（人天） | C27: 总产能 （人天） | D27: 超出工作量 | E27: 超出比例 | F27: 处理方式 | G27: 总产能 （28人天） | H27: 超出工作量 | I27: 超出比例 | M27: 封版时间 | N27: 上线时间 | O27: 工作日 | P27: 周六天数 | Q27: 开发周期 | R27: 是否采用
A28: APP开发-阳光云 | B28: =B16 -> 224.5 | C28: =B24*Q28 -> 128 | D28: =B28-C28 -> 96.5 | E28: =IFERROR(D28/C28,0) -> 0.75390625 | G28: =INDEX($B$24:$S$24,ROW(A1))*$Q$29 -> 224 | H28: =B28-G28 -> 0.5 | I28: =IFERROR(H28/G28,0) -> 0.0022321429 | N28: 7.30 | O28: 15 | P28: 1 | Q28: =SUM(O28:P28) -> 16
A29: APP开发-平台 | B29: =C16 -> 49 | C29: =C24*Q28 -> 0 | D29: =B29-C29 -> 49 | E29: =IFERROR(D29/C29,0) -> 0 | G29: =INDEX($B$24:$S$24,ROW(A2))*$Q$29 -> 0 | H29: =B29-G29 -> 49 | I29: =IFERROR(H29/G29,0) -> 0 | M29: 8.1 | N29: 8.13 | O29: 25 | P29: 3 | Q29: =SUM(O29:P29) -> 28
A30: 后端开发-阳光云 | B30: 294.1 | C30: =D24*Q28 -> 136 | D30: =B30-C30 -> 158.1 | E30: =IFERROR(D30/C30,0) -> 1.1625 | G30: =INDEX($B$24:$S$24,ROW(A3))*$Q$29 -> 238 | H30: =B30-G30 -> 56.1 | I30: =IFERROR(H30/G30,0) -> 0.23571429 | N30: 8.27 | O30: 35 | P30: 4 | Q30: =SUM(O30:P30) -> 39
A31: 后端开发-平台 | B31: 118 | C31: =E24*Q28 -> 72 | D31: =B31-C31 -> 46 | E31: =IFERROR(D31/C31,0) -> 0.63888889 | G31: =INDEX($B$24:$S$24,ROW(A4))*$Q$29 -> 126 | H31: =B31-G31 -> -8 | I31: =IFERROR(H31/G31,0) -> -0.063492063 | M31: 结论： 1、发布7.23小版本，发布8.13正式版本； 2、研发天数共 28天：工作日 25天，周末3天；
A32: Web开发-阳光云 | B32: =F16 -> 225.5 | C32: =F24*Q28 -> 91.2 | D32: =B32-C32 -> 134.3 | E32: =IFERROR(D32/C32,0) -> 1.4725877 | G32: =INDEX($B$24:$S$24,ROW(A5))*$Q$29 -> 159.6 | H32: =B32-G32 -> 65.9 | I32: =IFERROR(H32/G32,0) -> 0.41290727
A33: Web开发-平台 | B33: =G16 -> 0 | C33: =G24*Q28 -> 0 | D33: =B33-C33 -> 0 | E33: =IFERROR(D33/C33,0) -> 0 | G33: =INDEX($B$24:$S$24,ROW(A6))*$Q$29 -> 0 | H33: =B33-G33 -> 0 | I33: =IFERROR(H33/G33,0) -> 0
A34: 中台开发-IoT中台 | B34: =H16 -> 253 | C34: =H24*Q28 -> 144 | D34: =B34-C34 -> 109 | E34: =IFERROR(D34/C34,0) -> 0.75694444 | G34: =INDEX($B$24:$S$24,ROW(A7))*$Q$29 -> 252 | H34: =B34-G34 -> 1 | I34: =IFERROR(H34/G34,0) -> 0.003968254
A35: 中台开发-技术中台 | B35: =I16 -> 146 | C35: =I24*Q28 -> 80 | D35: =B35-C35 -> 66 | E35: =IFERROR(D35/C35,0) -> 0.825 | G35: =INDEX($B$24:$S$24,ROW(A8))*$Q$29 -> 140 | H35: =B35-G35 -> 6 | I35: =IFERROR(H35/G35,0) -> 0.042857143
A36: 中台开发-数据中台 | B36: =J16 -> 320 | C36: =J24*Q28 -> 176 | D36: =B36-C36 -> 144 | E36: =IFERROR(D36/C36,0) -> 0.81818182 | G36: =INDEX($B$24:$S$24,ROW(A9))*$Q$29 -> 308 | H36: =B36-G36 -> 12 | I36: =IFERROR(H36/G36,0) -> 0.038961039
A37: 中台开发-平台运维 | B37: =K16 -> 125 | C37: =K24*Q28 -> 96 | D37: =B37-C37 -> 29 | E37: =IFERROR(D37/C37,0) -> 0.30208333 | G37: =INDEX($B$24:$S$24,ROW(A10))*$Q$29 -> 168 | H37: =B37-G37 -> -43 | I37: =IFERROR(H37/G37,0) -> -0.25595238 | M37: 7.9 6月版本发布 | O37: 7.10研发周期开始
A38: AI开发-交互智能 | B38: =L16 -> 0 | C38: =L24*Q28 -> 0 | D38: =B38-C38 -> 0 | E38: =IFERROR(D38/C38,0) -> 0 | G38: =INDEX($B$24:$S$24,ROW(A11))*$Q$29 -> 0 | H38: =B38-G38 -> 0 | I38: =IFERROR(H38/G38,0) -> 0 | N38: 无月中小版本、7.30发布正式7月版本
A39: AI开发-系统智能 | B39: =M16 -> 0 | C39: =M24*Q28 -> 0 | D39: =B39-C39 -> 0 | E39: =IFERROR(D39/C39,0) -> 0 | G39: =INDEX($B$24:$S$24,ROW(A12))*$Q$29 -> 0 | H39: =B39-G39 -> 0 | I39: =IFERROR(H39/G39,0) -> 0 | M39: 方案二 | N39: 月中版本放7.23、7月正式版本放8.13
A40: 测试部-应用软件测试-云服务 | B40: =N16 -> 481 | C40: =N24*Q28 -> 264 | D40: =B40-C40 -> 217 | E40: =IFERROR(D40/C40,0) -> 0.8219697 | G40: =INDEX($B$24:$S$24,ROW(A13))*$Q$29 -> 462 | H40: =B40-G40 -> 19 | I40: =IFERROR(H40/G40,0) -> 0.041125541 | N40: 7&8月版本合并、7.30小版本、8.27大版本
A41: 测试部-应用软件测试-中后台 | B41: =O16 -> 129 | C41: =O24*Q28 -> 56 | D41: =B41-C41 -> 73 | E41: =IFERROR(D41/C41,0) -> 1.3035714 | G41: =INDEX($B$24:$S$24,ROW(A14))*$Q$29 -> 98 | H41: =B41-G41 -> 31 | I41: =IFERROR(H41/G41,0) -> 0.31632653 | M41: 备注 | N41: 7.30附近 印度云迁移人力占用
A42: 欧洲办公室-APP | B42: =P16 -> 15 | C42: =P24*Q28 -> 128 | D42: =B42-C42 -> -113 | E42: =IFERROR(D42/C42,0) -> -0.8828125 | G42: =INDEX($B$24:$S$24,ROW(A15))*$Q$29 -> 224 | H42: =B42-G42 -> -209 | I42: =IFERROR(H42/G42,0) -> -0.93303571
A43: 欧洲办公室-WEB | B43: =Q16 -> 10 | C43: =Q24*Q28 -> 48 | D43: =B43-C43 -> -38 | E43: =IFERROR(D43/C43,0) -> -0.79166667 | G43: =INDEX($B$24:$S$24,ROW(A16))*$Q$29 -> 84 | H43: =B43-G43 -> -74 | I43: =IFERROR(H43/G43,0) -> -0.88095238
A44: 欧洲办公室-测试 | B44: =R16 -> 18 | C44: =R24*Q28 -> 48 | D44: =B44-C44 -> -30 | E44: =IFERROR(D44/C44,0) -> -0.625 | G44: =INDEX($B$24:$S$24,ROW(A17))*$Q$29 -> 84 | H44: =B44-G44 -> -66 | I44: =IFERROR(H44/G44,0) -> -0.78571429
M45: =INDEX($B$24:$S$24,ROW(A11)) -> 0
...

Sheet 人力工时数据
A1: 所属项目(层级1) | B1: 所在团队 | C1: 阳光云2026-7月C版本迭代 | E1: 中后台-2026年7月迭代
C2: 故事点 (求和) | D2: 预估故事点 (求和) | E2: 故事点 (求和) | F2: 预估故事点 (求和) | H2: 项目_公式辅助列
A3: 智慧能源产品中心 | B3: 后端开发-阳光云 | C3: 227.5 | D3: 0 | E3: 0 | F3: 0 | H3: 智慧能源产品中心
B4: 中台开发-数据中台 | C4: 3 | D4: 0 | E4: 222 | F4: 0 | H4: 智慧能源产品中心
B5: 中台开发-IoT中台 | C5: 0 | D5: 0 | E5: 173 | F5: 0 | H5: 智慧能源产品中心
B6: WEB开发-阳光云 | C6: 148.5 | D6: 0 | E6: 0 | F6: 0 | H6: 智慧能源产品中心
B7: APP开发-阳光云 | C7: 112.5 | D7: 66 | E7: 0 | F7: 0 | H7: 智慧能源产品中心
B8: 中台开发-平台运维 | C8: 0 | D8: 0 | E8: 83 | F8: 0 | H8: 智慧能源产品中心
B9: 测试部-应用软件测试-中后台 | C9: 76 | D9: 0 | E9: 0 | F9: 0 | H9: 智慧能源产品中心
B10: 中台开发-技术中台 | C10: 0 | D10: 0 | E10: 74 | F10: 0 | H10: 智慧能源产品中心
B11: 后端开发-平台 | C11: 70 | D11: 0 | E11: 0 | F11: 0 | H11: 智慧能源产品中心
B12: APP开发-平台 | C12: 49 | D12: 0 | E12: 0 | F12: 0 | H12: 智慧能源产品中心
B13: 测试部-应用软件测试-云服务 | C13: 27 | D13: 266 | E13: 0 | F13: 0 | H13: 智慧能源产品中心
B14: 欧洲办公室-测试 | C14: 18 | D14: 0 | E14: 0 | F14: 0 | H14: 智慧能源产品中心
B15: 欧洲办公室-APP | C15: 15 | D15: 0 | E15: 0 | F15: 0 | H15: 智慧能源产品中心
B16: 欧洲办公室-WEB | C16: 10 | D16: 0 | E16: 0 | F16: 0 | H16: 智慧能源产品中心
A17: 户用及分布式监控 | B17: 后端开发-阳光云 | C17: 137.6 | D17: 0 | E17: 0 | F17: 0 | H17: 户用及分布式监控
B18: WEB开发-阳光云 | C18: 56.5 | D18: 0 | E18: 0 | F18: 0 | H18: 户用及分布式监控
B19: APP开发-阳光云 | C19: 56 | D19: 42 | E19: 0 | F19: 0 | H19: 户用及分布式监控
B20: 测试部-应用软件测试-中后台 | C20: 40 | D20: 0 | E20: 0 | F20: 0 | H20: 户用及分布式监控
B21: 中台开发-IoT中台 | C21: 0 | D21: 0 | E21: 39 | F21: 0 | H21: 户用及分布式监控
B22: 中台开发-平台运维 | C22: 0 | D22: 0 | E22: 37 | F22: 0 | H22: 户用及分布式监控
B23: 中台开发-数据中台 | C23: 0 | D23: 0 | E23: 33 | F23: 0 | H23: 户用及分布式监控
B24: 后端开发-平台 | C24: 19 | D24: 0 | E24: 0 | F24: 0 | H24: 户用及分布式监控
B25: 测试部-应用软件测试-云服务 | C25: 6 | D25: 125 | E25: 0 | F25: 0 | H25: 户用及分布式监控
A26: 未立项 | B26: 中台开发-技术中台 | C26: 0 | D26: 0 | E26: 72 | F26: 33 | H26: 未立项
B27: 后端开发-阳光云 | C27: 9 | D27: 0 | E27: 0 | F27: 0 | H27: 未立项
B28: 中台开发-数据中台 | C28: 0 | D28: 0 | E28: 5 | F28: 0 | H28: 未立项
B29: 后端开发-平台 | C29: 3 | D29: 0 | E29: 0 | F29: 0 | H29: 未立项
B30: WEB开发-阳光云 | C30: 2.5 | D30: 0 | E30: 0 | F30: 0 | H30: 未立项
B31: 测试部-应用软件测试-中后台 | C31: 1.5 | D31: 0 | E31: 0 | F31: 0 | H31: 未立项
B32: 中台开发-IoT中台 | C32: 0 | D32: 0 | E32: 1 | F32: 0 | H32: 未立项
B33: 测试部-应用软件测试-云服务 | C33: 0 | D33: 2 | E33: 0 | F33: 0 | H33: 未立项
A34: 储能及地面监控 | B34: APP开发-阳光云 | C34: 47 | D34: 0 | E34: 0 | F34: 0 | H34: 储能及地面监控
B35: 后端开发-阳光云 | C35: 46 | D35: 0 | E35: 0 | F35: 0 | H35: 储能及地面监控
B36: 中台开发-数据中台 | C36: 0 | D36: 0 | E36: 16 | F36: 0 | H36: 储能及地面监控
B37: WEB开发-阳光云 | C37: 15 | D37: 0 | E37: 0 | F37: 0 | H37: 储能及地面监控
B38: 测试部-应用软件测试-云服务 | C38: 6 | D38: 66.5 | E38: 0 | F38: 0 | H38: 储能及地面监控
B39: 测试部-应用软件测试-中后台 | C39: 5 | D39: 0 | E39: 0 | F39: 0 | H39: 储能及地面监控
B40: 中台开发-平台运维 | C40: 0 | D40: 0 | E40: 5 | F40: 0 | H40: 储能及地面监控
...
